[2023-03-29T01:41:30.847+0000] {taskinstance.py:1084} INFO - Dependencies all met for dep_context=non-requeueable deps ti=<TaskInstance: my_dag.extract_and_load scheduled__2023-03-29T01:10:00+00:00 [queued]>
[2023-03-29T01:41:30.896+0000] {taskinstance.py:1084} INFO - Dependencies all met for dep_context=requeueable deps ti=<TaskInstance: my_dag.extract_and_load scheduled__2023-03-29T01:10:00+00:00 [queued]>
[2023-03-29T01:41:30.898+0000] {taskinstance.py:1282} INFO - 
--------------------------------------------------------------------------------
[2023-03-29T01:41:30.900+0000] {taskinstance.py:1283} INFO - Starting attempt 1 of 1
[2023-03-29T01:41:30.902+0000] {taskinstance.py:1284} INFO - 
--------------------------------------------------------------------------------
[2023-03-29T01:41:30.976+0000] {taskinstance.py:1303} INFO - Executing <Task(PythonOperator): extract_and_load> on 2023-03-29 01:10:00+00:00
[2023-03-29T01:41:31.077+0000] {standard_task_runner.py:55} INFO - Started process 1086 to run task
[2023-03-29T01:41:31.114+0000] {standard_task_runner.py:82} INFO - Running: ['***', 'tasks', 'run', 'my_dag', 'extract_and_load', 'scheduled__2023-03-29T01:10:00+00:00', '--job-id', '288', '--raw', '--subdir', 'DAGS_FOLDER/test.py', '--cfg-path', '/tmp/tmp4bvhd6tx']
[2023-03-29T01:41:31.133+0000] {standard_task_runner.py:83} INFO - Job 288: Subtask extract_and_load
[2023-03-29T01:41:31.440+0000] {task_command.py:388} INFO - Running <TaskInstance: my_dag.extract_and_load scheduled__2023-03-29T01:10:00+00:00 [running]> on host 18cf4662f3ac
[2023-03-29T01:41:31.859+0000] {taskinstance.py:1511} INFO - Exporting the following env vars:
AIRFLOW_CTX_DAG_OWNER=***
AIRFLOW_CTX_DAG_ID=my_dag
AIRFLOW_CTX_TASK_ID=extract_and_load
AIRFLOW_CTX_EXECUTION_DATE=2023-03-29T01:10:00+00:00
AIRFLOW_CTX_TRY_NUMBER=1
AIRFLOW_CTX_DAG_RUN_ID=scheduled__2023-03-29T01:10:00+00:00
[2023-03-29T01:41:31.867+0000] {logging_mixin.py:137} INFO - eeeee test-chronotruck test-chr-ml/primary/data.csv
[2023-03-29T01:57:57.122+0000] {taskinstance.py:1775} ERROR - Task failed with exception
Traceback (most recent call last):
  File "/home/airflow/.local/lib/python3.7/site-packages/airflow/operators/python.py", line 175, in execute
    return_value = self.execute_callable()
  File "/home/airflow/.local/lib/python3.7/site-packages/airflow/operators/python.py", line 192, in execute_callable
    return self.python_callable(*self.op_args, **self.op_kwargs)
  File "/opt/airflow/dags/test.py", line 66, in load_csv_from_bucket
    blob.download_to_filename("/tmp/" + filename)
  File "/home/airflow/.local/lib/python3.7/site-packages/google/cloud/storage/blob.py", line 1270, in download_to_filename
    retry=retry,
  File "/home/airflow/.local/lib/python3.7/site-packages/google/cloud/storage/client.py", line 1096, in download_blob_to_file
    retry=retry,
  File "/home/airflow/.local/lib/python3.7/site-packages/google/cloud/storage/blob.py", line 984, in _do_download
    response = download.consume(transport, timeout=timeout)
  File "/home/airflow/.local/lib/python3.7/site-packages/google/resumable_media/requests/download.py", line 238, in consume
    retriable_request, self._get_status_code, self._retry_strategy
  File "/home/airflow/.local/lib/python3.7/site-packages/google/resumable_media/requests/_request_helpers.py", line 148, in wait_and_retry
    response = func()
  File "/home/airflow/.local/lib/python3.7/site-packages/google/resumable_media/requests/download.py", line 233, in retriable_request
    self._write_to_stream(result)
  File "/home/airflow/.local/lib/python3.7/site-packages/google/resumable_media/requests/download.py", line 141, in _write_to_stream
    raise common.DataCorruption(response, msg)
google.resumable_media.common.DataCorruption: Checksum mismatch while downloading:

  https://storage.googleapis.com/download/storage/v1/b/test-chr-ml/o/primary%2Fdata.csv%2Fcensus_income_learn.csv?generation=1679778413585655&alt=media

The X-Goog-Hash header indicated an MD5 checksum of:

  iH9NxBCpm8MyvduwpBlbiA==

but the actual MD5 checksum of the downloaded contents was:

  i7T7Hy7XkmLEBbB8dIL4Hw==

[2023-03-29T01:57:59.928+0000] {taskinstance.py:1326} INFO - Marking task as FAILED. dag_id=my_dag, task_id=extract_and_load, execution_date=20230329T011000, start_date=20230329T014130, end_date=20230329T015759
[2023-03-29T01:58:01.335+0000] {standard_task_runner.py:105} ERROR - Failed to execute job 288 for task extract_and_load (Checksum mismatch while downloading:

  https://storage.googleapis.com/download/storage/v1/b/test-chr-ml/o/primary%2Fdata.csv%2Fcensus_income_learn.csv?generation=1679778413585655&alt=media

The X-Goog-Hash header indicated an MD5 checksum of:

  iH9NxBCpm8MyvduwpBlbiA==

but the actual MD5 checksum of the downloaded contents was:

  i7T7Hy7XkmLEBbB8dIL4Hw==
; 1086)
[2023-03-29T01:58:09.853+0000] {local_task_job.py:212} INFO - Task exited with return code 1
[2023-03-29T01:58:14.347+0000] {taskinstance.py:2585} INFO - 0 downstream tasks scheduled from follow-on schedule check
