[2023-03-29T12:00:05.430+0000] {taskinstance.py:1084} INFO - Dependencies all met for dep_context=non-requeueable deps ti=<TaskInstance: my_dag.extract_and_load scheduled__2023-03-29T11:55:00+00:00 [queued]>
[2023-03-29T12:00:05.448+0000] {taskinstance.py:1084} INFO - Dependencies all met for dep_context=requeueable deps ti=<TaskInstance: my_dag.extract_and_load scheduled__2023-03-29T11:55:00+00:00 [queued]>
[2023-03-29T12:00:05.450+0000] {taskinstance.py:1282} INFO - 
--------------------------------------------------------------------------------
[2023-03-29T12:00:05.451+0000] {taskinstance.py:1283} INFO - Starting attempt 1 of 1
[2023-03-29T12:00:05.452+0000] {taskinstance.py:1284} INFO - 
--------------------------------------------------------------------------------
[2023-03-29T12:00:05.479+0000] {taskinstance.py:1303} INFO - Executing <Task(PythonOperator): extract_and_load> on 2023-03-29 11:55:00+00:00
[2023-03-29T12:00:05.498+0000] {standard_task_runner.py:55} INFO - Started process 1451 to run task
[2023-03-29T12:00:05.509+0000] {standard_task_runner.py:82} INFO - Running: ['***', 'tasks', 'run', 'my_dag', 'extract_and_load', 'scheduled__2023-03-29T11:55:00+00:00', '--job-id', '356', '--raw', '--subdir', 'DAGS_FOLDER/test.py', '--cfg-path', '/tmp/tmpiogpepo8']
[2023-03-29T12:00:05.515+0000] {standard_task_runner.py:83} INFO - Job 356: Subtask extract_and_load
[2023-03-29T12:00:05.664+0000] {task_command.py:388} INFO - Running <TaskInstance: my_dag.extract_and_load scheduled__2023-03-29T11:55:00+00:00 [running]> on host e7ec0deaf382
[2023-03-29T12:00:05.813+0000] {taskinstance.py:1511} INFO - Exporting the following env vars:
AIRFLOW_CTX_DAG_OWNER=***
AIRFLOW_CTX_DAG_ID=my_dag
AIRFLOW_CTX_TASK_ID=extract_and_load
AIRFLOW_CTX_EXECUTION_DATE=2023-03-29T11:55:00+00:00
AIRFLOW_CTX_TRY_NUMBER=1
AIRFLOW_CTX_DAG_RUN_ID=scheduled__2023-03-29T11:55:00+00:00
[2023-03-29T12:00:05.816+0000] {logging_mixin.py:137} INFO - eeeee test-chronotruck test-chr-ml/primary/data.csv
[2023-03-29T12:00:16.040+0000] {logging_mixin.py:137} INFO - rasssss
[2023-03-29T12:07:41.010+0000] {taskinstance.py:1775} ERROR - Task failed with exception
Traceback (most recent call last):
  File "/home/airflow/.local/lib/python3.7/site-packages/google/cloud/bigquery/client.py", line 2452, in load_table_from_file
    file_obj, job_resource, size, num_retries, timeout, project=project
  File "/home/airflow/.local/lib/python3.7/site-packages/google/cloud/bigquery/client.py", line 3022, in _do_multipart_upload
    self._http, data, metadata, _GENERIC_CONTENT_TYPE, timeout=timeout
  File "/home/airflow/.local/lib/python3.7/site-packages/google/resumable_media/requests/upload.py", line 154, in transmit
    retriable_request, self._get_status_code, self._retry_strategy
  File "/home/airflow/.local/lib/python3.7/site-packages/google/resumable_media/requests/_request_helpers.py", line 148, in wait_and_retry
    response = func()
  File "/home/airflow/.local/lib/python3.7/site-packages/google/resumable_media/requests/upload.py", line 149, in retriable_request
    self._process_response(result)
  File "/home/airflow/.local/lib/python3.7/site-packages/google/resumable_media/_upload.py", line 114, in _process_response
    _helpers.require_status_code(response, (http.client.OK,), self._get_status_code)
  File "/home/airflow/.local/lib/python3.7/site-packages/google/resumable_media/_helpers.py", line 113, in require_status_code
    *status_codes
google.resumable_media.common.InvalidResponse: ('Request failed with status code', 409, 'Expected one of', <HTTPStatus.OK: 200>)

During handling of the above exception, another exception occurred:

Traceback (most recent call last):
  File "/home/airflow/.local/lib/python3.7/site-packages/pandas_gbq/gbq.py", line 599, in load_data
    billing_project=billing_project,
  File "/home/airflow/.local/lib/python3.7/site-packages/pandas_gbq/load.py", line 246, in load_chunks
    billing_project=billing_project,
  File "/home/airflow/.local/lib/python3.7/site-packages/pandas_gbq/load.py", line 136, in load_parquet
    project=billing_project,
  File "/home/airflow/.local/lib/python3.7/site-packages/google/cloud/bigquery/client.py", line 2713, in load_table_from_dataframe
    timeout=timeout,
  File "/home/airflow/.local/lib/python3.7/site-packages/google/cloud/bigquery/client.py", line 2455, in load_table_from_file
    raise exceptions.from_http_response(exc.response)
google.api_core.exceptions.Conflict: 409 POST https://bigquery.googleapis.com/upload/bigquery/v2/projects/test-chronotruck/jobs?uploadType=multipart: Already Exists: Job test-chronotruck:US.6d3e64bc-d6e5-490a-94ff-132f02d3a5a3

During handling of the above exception, another exception occurred:

Traceback (most recent call last):
  File "/home/airflow/.local/lib/python3.7/site-packages/airflow/operators/python.py", line 175, in execute
    return_value = self.execute_callable()
  File "/home/airflow/.local/lib/python3.7/site-packages/airflow/operators/python.py", line 192, in execute_callable
    return self.python_callable(*self.op_args, **self.op_kwargs)
  File "/opt/airflow/dags/test.py", line 94, in load_csv_from_bucket
    {'name':'tax_filer_status','type': 'STRING'}
  File "/home/airflow/.local/lib/python3.7/site-packages/pandas_gbq/gbq.py", line 1205, in to_gbq
    billing_project=project_id,
  File "/home/airflow/.local/lib/python3.7/site-packages/pandas_gbq/gbq.py", line 610, in load_data
    self.process_http_error(ex)
  File "/home/airflow/.local/lib/python3.7/site-packages/pandas_gbq/gbq.py", line 386, in process_http_error
    raise GenericGBQException("Reason: {0}".format(ex))
pandas_gbq.exceptions.GenericGBQException: Reason: 409 POST https://bigquery.googleapis.com/upload/bigquery/v2/projects/test-chronotruck/jobs?uploadType=multipart: Already Exists: Job test-chronotruck:US.6d3e64bc-d6e5-490a-94ff-132f02d3a5a3
[2023-03-29T12:07:41.176+0000] {taskinstance.py:1326} INFO - Marking task as FAILED. dag_id=my_dag, task_id=extract_and_load, execution_date=20230329T115500, start_date=20230329T120005, end_date=20230329T120741
[2023-03-29T12:07:41.408+0000] {standard_task_runner.py:105} ERROR - Failed to execute job 356 for task extract_and_load (Reason: 409 POST https://bigquery.googleapis.com/upload/bigquery/v2/projects/test-chronotruck/jobs?uploadType=multipart: Already Exists: Job test-chronotruck:US.6d3e64bc-d6e5-490a-94ff-132f02d3a5a3; 1451)
[2023-03-29T12:07:42.348+0000] {local_task_job.py:212} INFO - Task exited with return code 1
[2023-03-29T12:07:42.656+0000] {taskinstance.py:2585} INFO - 0 downstream tasks scheduled from follow-on schedule check
