[2023-03-29T23:13:06.648+0000] {taskinstance.py:1084} INFO - Dependencies all met for dep_context=non-requeueable deps ti=<TaskInstance: tax_income.extract_and_load scheduled__2023-03-27T05:00:00+00:00 [queued]>
[2023-03-29T23:13:06.670+0000] {taskinstance.py:1084} INFO - Dependencies all met for dep_context=requeueable deps ti=<TaskInstance: tax_income.extract_and_load scheduled__2023-03-27T05:00:00+00:00 [queued]>
[2023-03-29T23:13:06.672+0000] {taskinstance.py:1282} INFO - 
--------------------------------------------------------------------------------
[2023-03-29T23:13:06.673+0000] {taskinstance.py:1283} INFO - Starting attempt 1 of 2
[2023-03-29T23:13:06.675+0000] {taskinstance.py:1284} INFO - 
--------------------------------------------------------------------------------
[2023-03-29T23:13:06.714+0000] {taskinstance.py:1303} INFO - Executing <Task(PythonOperator): extract_and_load> on 2023-03-27 05:00:00+00:00
[2023-03-29T23:13:06.745+0000] {standard_task_runner.py:55} INFO - Started process 205 to run task
[2023-03-29T23:13:06.803+0000] {standard_task_runner.py:82} INFO - Running: ['***', 'tasks', 'run', 'tax_income', 'extract_and_load', 'scheduled__2023-03-27T05:00:00+00:00', '--job-id', '562', '--raw', '--subdir', 'DAGS_FOLDER/test.py', '--cfg-path', '/tmp/tmphzcwxq4x']
[2023-03-29T23:13:06.820+0000] {standard_task_runner.py:83} INFO - Job 562: Subtask extract_and_load
[2023-03-29T23:13:07.431+0000] {task_command.py:388} INFO - Running <TaskInstance: tax_income.extract_and_load scheduled__2023-03-27T05:00:00+00:00 [running]> on host 32688d23169d
[2023-03-29T23:13:08.131+0000] {taskinstance.py:1511} INFO - Exporting the following env vars:
AIRFLOW_CTX_DAG_OWNER=***
AIRFLOW_CTX_DAG_ID=tax_income
AIRFLOW_CTX_TASK_ID=extract_and_load
AIRFLOW_CTX_EXECUTION_DATE=2023-03-27T05:00:00+00:00
AIRFLOW_CTX_TRY_NUMBER=1
AIRFLOW_CTX_DAG_RUN_ID=scheduled__2023-03-27T05:00:00+00:00
[2023-03-29T23:13:08.143+0000] {test.py:66} INFO - Starting load_csv_from_bucket function...
[2023-03-29T23:13:08.376+0000] {test.py:75} INFO - Downloading CSV files from test-chr-ml 
[2023-03-29T23:13:30.760+0000] {test.py:91} INFO - Concatenating CSV files into a single DataFrame...
[2023-03-29T23:13:42.197+0000] {test.py:99} INFO - Select specific columns and rename them
[2023-03-29T23:13:42.797+0000] {test.py:106} INFO - Exporting DataFrame to BigQuery...
[2023-03-29T23:14:39.868+0000] {taskinstance.py:1775} ERROR - Task failed with exception
Traceback (most recent call last):
  File "/home/airflow/.local/lib/python3.7/site-packages/pandas_gbq/gbq.py", line 599, in load_data
    billing_project=billing_project,
  File "/home/airflow/.local/lib/python3.7/site-packages/pandas_gbq/load.py", line 246, in load_chunks
    billing_project=billing_project,
  File "/home/airflow/.local/lib/python3.7/site-packages/pandas_gbq/load.py", line 136, in load_parquet
    project=billing_project,
  File "/home/airflow/.local/lib/python3.7/site-packages/google/cloud/bigquery/job/base.py", line 728, in result
    return super(_AsyncJob, self).result(timeout=timeout, **kwargs)
  File "/home/airflow/.local/lib/python3.7/site-packages/google/api_core/future/polling.py", line 137, in result
    raise self._exception
google.api_core.exceptions.NotFound: 404 Not found: Table test-chronotruck:datawarehouse.tax was not found in location US

During handling of the above exception, another exception occurred:

Traceback (most recent call last):
  File "/home/airflow/.local/lib/python3.7/site-packages/airflow/operators/python.py", line 175, in execute
    return_value = self.execute_callable()
  File "/home/airflow/.local/lib/python3.7/site-packages/airflow/operators/python.py", line 192, in execute_callable
    return self.python_callable(*self.op_args, **self.op_kwargs)
  File "/opt/airflow/dags/test.py", line 118, in load_csv_from_bucket
    {'name':'tax_filer_stat','type': 'STRING'}
  File "/home/airflow/.local/lib/python3.7/site-packages/pandas_gbq/gbq.py", line 1205, in to_gbq
    billing_project=project_id,
  File "/home/airflow/.local/lib/python3.7/site-packages/pandas_gbq/gbq.py", line 610, in load_data
    self.process_http_error(ex)
  File "/home/airflow/.local/lib/python3.7/site-packages/pandas_gbq/gbq.py", line 386, in process_http_error
    raise GenericGBQException("Reason: {0}".format(ex))
pandas_gbq.exceptions.GenericGBQException: Reason: 404 Not found: Table test-chronotruck:datawarehouse.tax was not found in location US
[2023-03-29T23:14:40.059+0000] {taskinstance.py:1326} INFO - Marking task as UP_FOR_RETRY. dag_id=tax_income, task_id=extract_and_load, execution_date=20230327T050000, start_date=20230329T231306, end_date=20230329T231440
[2023-03-29T23:14:40.321+0000] {standard_task_runner.py:105} ERROR - Failed to execute job 562 for task extract_and_load (Reason: 404 Not found: Table test-chronotruck:datawarehouse.tax was not found in location US; 205)
[2023-03-29T23:14:43.038+0000] {local_task_job.py:212} INFO - Task exited with return code 1
[2023-03-29T23:14:44.533+0000] {taskinstance.py:2585} INFO - 0 downstream tasks scheduled from follow-on schedule check
