[2023-03-29T23:15:06.502+0000] {taskinstance.py:1084} INFO - Dependencies all met for dep_context=non-requeueable deps ti=<TaskInstance: tax_income.extract_and_load scheduled__2023-03-27T05:00:00+00:00 [queued]>
[2023-03-29T23:15:06.677+0000] {taskinstance.py:1084} INFO - Dependencies all met for dep_context=requeueable deps ti=<TaskInstance: tax_income.extract_and_load scheduled__2023-03-27T05:00:00+00:00 [queued]>
[2023-03-29T23:15:06.680+0000] {taskinstance.py:1282} INFO - 
--------------------------------------------------------------------------------
[2023-03-29T23:15:06.682+0000] {taskinstance.py:1283} INFO - Starting attempt 2 of 2
[2023-03-29T23:15:06.688+0000] {taskinstance.py:1284} INFO - 
--------------------------------------------------------------------------------
[2023-03-29T23:15:06.757+0000] {taskinstance.py:1303} INFO - Executing <Task(PythonOperator): extract_and_load> on 2023-03-27 05:00:00+00:00
[2023-03-29T23:15:06.784+0000] {standard_task_runner.py:55} INFO - Started process 247 to run task
[2023-03-29T23:15:06.825+0000] {standard_task_runner.py:82} INFO - Running: ['***', 'tasks', 'run', 'tax_income', 'extract_and_load', 'scheduled__2023-03-27T05:00:00+00:00', '--job-id', '566', '--raw', '--subdir', 'DAGS_FOLDER/test.py', '--cfg-path', '/tmp/tmpcfcn0cj5']
[2023-03-29T23:15:06.831+0000] {standard_task_runner.py:83} INFO - Job 566: Subtask extract_and_load
[2023-03-29T23:15:07.852+0000] {task_command.py:388} INFO - Running <TaskInstance: tax_income.extract_and_load scheduled__2023-03-27T05:00:00+00:00 [running]> on host 32688d23169d
[2023-03-29T23:15:09.715+0000] {taskinstance.py:1511} INFO - Exporting the following env vars:
AIRFLOW_CTX_DAG_OWNER=***
AIRFLOW_CTX_DAG_ID=tax_income
AIRFLOW_CTX_TASK_ID=extract_and_load
AIRFLOW_CTX_EXECUTION_DATE=2023-03-27T05:00:00+00:00
AIRFLOW_CTX_TRY_NUMBER=2
AIRFLOW_CTX_DAG_RUN_ID=scheduled__2023-03-27T05:00:00+00:00
[2023-03-29T23:15:09.733+0000] {test.py:66} INFO - Starting load_csv_from_bucket function...
[2023-03-29T23:15:10.214+0000] {test.py:75} INFO - Downloading CSV files from test-chr-ml 
[2023-03-29T23:15:27.491+0000] {test.py:91} INFO - Concatenating CSV files into a single DataFrame...
[2023-03-29T23:15:38.781+0000] {test.py:99} INFO - Select specific columns and rename them
[2023-03-29T23:15:39.080+0000] {test.py:106} INFO - Exporting DataFrame to BigQuery...
[2023-03-29T23:15:42.555+0000] {taskinstance.py:1775} ERROR - Task failed with exception
Traceback (most recent call last):
  File "/home/airflow/.local/lib/python3.7/site-packages/pandas_gbq/gbq.py", line 1329, in create
    self.client.create_table(table)
  File "/home/airflow/.local/lib/python3.7/site-packages/google/cloud/bigquery/client.py", line 755, in create_table
    timeout=timeout,
  File "/home/airflow/.local/lib/python3.7/site-packages/google/cloud/bigquery/client.py", line 782, in _call_api
    return call()
  File "/home/airflow/.local/lib/python3.7/site-packages/google/api_core/retry.py", line 288, in retry_wrapped_func
    on_error=on_error,
  File "/home/airflow/.local/lib/python3.7/site-packages/google/api_core/retry.py", line 190, in retry_target
    return target()
  File "/home/airflow/.local/lib/python3.7/site-packages/google/cloud/_http/__init__.py", line 494, in api_request
    raise exceptions.from_http_response(response)
google.api_core.exceptions.Conflict: 409 POST https://bigquery.googleapis.com/bigquery/v2/projects/test-chronotruck/datasets/datawarehouse/tables?prettyPrint=false: Already Exists: Table test-chronotruck:datawarehouse.tax

During handling of the above exception, another exception occurred:

Traceback (most recent call last):
  File "/home/airflow/.local/lib/python3.7/site-packages/airflow/operators/python.py", line 175, in execute
    return_value = self.execute_callable()
  File "/home/airflow/.local/lib/python3.7/site-packages/airflow/operators/python.py", line 192, in execute_callable
    return self.python_callable(*self.op_args, **self.op_kwargs)
  File "/opt/airflow/dags/test.py", line 118, in load_csv_from_bucket
    {'name':'tax_filer_stat','type': 'STRING'}
  File "/home/airflow/.local/lib/python3.7/site-packages/pandas_gbq/gbq.py", line 1175, in to_gbq
    project_id_table, dataset_id, table_id, table_schema
  File "/home/airflow/.local/lib/python3.7/site-packages/pandas_gbq/gbq.py", line 615, in delete_and_recreate_table
    table.create(table_id, table_schema)
  File "/home/airflow/.local/lib/python3.7/site-packages/pandas_gbq/gbq.py", line 1331, in create
    self.process_http_error(ex)
  File "/home/airflow/.local/lib/python3.7/site-packages/pandas_gbq/gbq.py", line 386, in process_http_error
    raise GenericGBQException("Reason: {0}".format(ex))
pandas_gbq.exceptions.GenericGBQException: Reason: 409 POST https://bigquery.googleapis.com/bigquery/v2/projects/test-chronotruck/datasets/datawarehouse/tables?prettyPrint=false: Already Exists: Table test-chronotruck:datawarehouse.tax
[2023-03-29T23:15:44.852+0000] {taskinstance.py:1326} INFO - Marking task as FAILED. dag_id=tax_income, task_id=extract_and_load, execution_date=20230327T050000, start_date=20230329T231506, end_date=20230329T231544
[2023-03-29T23:15:45.355+0000] {standard_task_runner.py:105} ERROR - Failed to execute job 566 for task extract_and_load (Reason: 409 POST https://bigquery.googleapis.com/bigquery/v2/projects/test-chronotruck/datasets/datawarehouse/tables?prettyPrint=false: Already Exists: Table test-chronotruck:datawarehouse.tax; 247)
[2023-03-29T23:15:45.764+0000] {local_task_job.py:212} INFO - Task exited with return code 1
[2023-03-29T23:15:45.884+0000] {taskinstance.py:2585} INFO - 0 downstream tasks scheduled from follow-on schedule check
