[2023-03-29T13:55:30.081+0000] {taskinstance.py:1084} INFO - Dependencies all met for dep_context=non-requeueable deps ti=<TaskInstance: my_dag.model_predict scheduled__2023-03-29T13:45:00+00:00 [queued]>
[2023-03-29T13:55:30.127+0000] {taskinstance.py:1084} INFO - Dependencies all met for dep_context=requeueable deps ti=<TaskInstance: my_dag.model_predict scheduled__2023-03-29T13:45:00+00:00 [queued]>
[2023-03-29T13:55:30.129+0000] {taskinstance.py:1282} INFO - 
--------------------------------------------------------------------------------
[2023-03-29T13:55:30.131+0000] {taskinstance.py:1283} INFO - Starting attempt 1 of 1
[2023-03-29T13:55:30.134+0000] {taskinstance.py:1284} INFO - 
--------------------------------------------------------------------------------
[2023-03-29T13:55:30.217+0000] {taskinstance.py:1303} INFO - Executing <Task(PythonOperator): model_predict> on 2023-03-29 13:45:00+00:00
[2023-03-29T13:55:30.253+0000] {standard_task_runner.py:55} INFO - Started process 2541 to run task
[2023-03-29T13:55:30.275+0000] {standard_task_runner.py:82} INFO - Running: ['***', 'tasks', 'run', 'my_dag', 'model_predict', 'scheduled__2023-03-29T13:45:00+00:00', '--job-id', '399', '--raw', '--subdir', 'DAGS_FOLDER/test.py', '--cfg-path', '/tmp/tmp_5zpjuiw']
[2023-03-29T13:55:30.305+0000] {standard_task_runner.py:83} INFO - Job 399: Subtask model_predict
[2023-03-29T13:55:30.669+0000] {task_command.py:388} INFO - Running <TaskInstance: my_dag.model_predict scheduled__2023-03-29T13:45:00+00:00 [running]> on host e7ec0deaf382
[2023-03-29T13:55:31.079+0000] {taskinstance.py:1511} INFO - Exporting the following env vars:
AIRFLOW_CTX_DAG_OWNER=***
AIRFLOW_CTX_DAG_ID=my_dag
AIRFLOW_CTX_TASK_ID=model_predict
AIRFLOW_CTX_EXECUTION_DATE=2023-03-29T13:45:00+00:00
AIRFLOW_CTX_TRY_NUMBER=1
AIRFLOW_CTX_DAG_RUN_ID=scheduled__2023-03-29T13:45:00+00:00
[2023-03-29T13:55:34.318+0000] {warnings.py:110} WARNING - /home/***/.local/lib/python3.7/site-packages/google/cloud/bigquery/table.py:1988: UserWarning: A progress bar was requested, but there was an error loading the tqdm library. Please install tqdm to use the progress bar functionality.
  create_bqstorage_client=create_bqstorage_client,

[2023-03-29T13:55:47.523+0000] {gbq.py:352} INFO - Total time taken 15.75 s.
Finished at 2023-03-29 13:55:47.
[2023-03-29T13:55:47.539+0000] {taskinstance.py:1775} ERROR - Task failed with exception
Traceback (most recent call last):
  File "/home/airflow/.local/lib/python3.7/site-packages/pandas/core/indexes/base.py", line 3361, in get_loc
    return self._engine.get_loc(casted_key)
  File "pandas/_libs/index.pyx", line 76, in pandas._libs.index.IndexEngine.get_loc
  File "pandas/_libs/index.pyx", line 108, in pandas._libs.index.IndexEngine.get_loc
  File "pandas/_libs/hashtable_class_helper.pxi", line 5198, in pandas._libs.hashtable.PyObjectHashTable.get_item
  File "pandas/_libs/hashtable_class_helper.pxi", line 5206, in pandas._libs.hashtable.PyObjectHashTable.get_item
KeyError: 'tax_filer_status'

The above exception was the direct cause of the following exception:

Traceback (most recent call last):
  File "/home/airflow/.local/lib/python3.7/site-packages/airflow/operators/python.py", line 175, in execute
    return_value = self.execute_callable()
  File "/home/airflow/.local/lib/python3.7/site-packages/airflow/operators/python.py", line 192, in execute_callable
    return self.python_callable(*self.op_args, **self.op_kwargs)
  File "/opt/airflow/dags/test.py", line 114, in model_predict
    features=df.pop("tax_filer_status")
  File "/home/airflow/.local/lib/python3.7/site-packages/pandas/core/frame.py", line 5226, in pop
    return super().pop(item=item)
  File "/home/airflow/.local/lib/python3.7/site-packages/pandas/core/generic.py", line 870, in pop
    result = self[item]
  File "/home/airflow/.local/lib/python3.7/site-packages/pandas/core/frame.py", line 3458, in __getitem__
    indexer = self.columns.get_loc(key)
  File "/home/airflow/.local/lib/python3.7/site-packages/pandas/core/indexes/base.py", line 3363, in get_loc
    raise KeyError(key) from err
KeyError: 'tax_filer_status'
[2023-03-29T13:55:47.629+0000] {taskinstance.py:1326} INFO - Marking task as FAILED. dag_id=my_dag, task_id=model_predict, execution_date=20230329T134500, start_date=20230329T135530, end_date=20230329T135547
[2023-03-29T13:55:47.679+0000] {standard_task_runner.py:105} ERROR - Failed to execute job 399 for task model_predict ('tax_filer_status'; 2541)
[2023-03-29T13:55:47.862+0000] {local_task_job.py:212} INFO - Task exited with return code 1
[2023-03-29T13:55:47.920+0000] {taskinstance.py:2585} INFO - 0 downstream tasks scheduled from follow-on schedule check
