[2023-03-29T14:26:46.634+0000] {taskinstance.py:1084} INFO - Dependencies all met for dep_context=non-requeueable deps ti=<TaskInstance: my_dag.extract_and_load scheduled__2023-03-29T14:20:00+00:00 [queued]>
[2023-03-29T14:26:46.903+0000] {taskinstance.py:1084} INFO - Dependencies all met for dep_context=requeueable deps ti=<TaskInstance: my_dag.extract_and_load scheduled__2023-03-29T14:20:00+00:00 [queued]>
[2023-03-29T14:26:46.908+0000] {taskinstance.py:1282} INFO - 
--------------------------------------------------------------------------------
[2023-03-29T14:26:46.913+0000] {taskinstance.py:1283} INFO - Starting attempt 1 of 1
[2023-03-29T14:26:46.916+0000] {taskinstance.py:1284} INFO - 
--------------------------------------------------------------------------------
[2023-03-29T14:26:47.392+0000] {taskinstance.py:1303} INFO - Executing <Task(PythonOperator): extract_and_load> on 2023-03-29 14:20:00+00:00
[2023-03-29T14:26:48.371+0000] {standard_task_runner.py:55} INFO - Started process 2582 to run task
[2023-03-29T14:26:50.717+0000] {standard_task_runner.py:82} INFO - Running: ['***', 'tasks', 'run', 'my_dag', 'extract_and_load', 'scheduled__2023-03-29T14:20:00+00:00', '--job-id', '402', '--raw', '--subdir', 'DAGS_FOLDER/test.py', '--cfg-path', '/tmp/tmplhzwmycs']
[2023-03-29T14:26:50.972+0000] {standard_task_runner.py:83} INFO - Job 402: Subtask extract_and_load
[2023-03-29T14:26:52.217+0000] {task_command.py:388} INFO - Running <TaskInstance: my_dag.extract_and_load scheduled__2023-03-29T14:20:00+00:00 [running]> on host e7ec0deaf382
[2023-03-29T14:26:53.068+0000] {taskinstance.py:1511} INFO - Exporting the following env vars:
AIRFLOW_CTX_DAG_OWNER=***
AIRFLOW_CTX_DAG_ID=my_dag
AIRFLOW_CTX_TASK_ID=extract_and_load
AIRFLOW_CTX_EXECUTION_DATE=2023-03-29T14:20:00+00:00
AIRFLOW_CTX_TRY_NUMBER=1
AIRFLOW_CTX_DAG_RUN_ID=scheduled__2023-03-29T14:20:00+00:00
[2023-03-29T14:26:53.074+0000] {logging_mixin.py:137} INFO - eeeee test-chronotruck test-chr-ml/primary/data.csv
[2023-03-29T14:44:28.428+0000] {taskinstance.py:1775} ERROR - Task failed with exception
Traceback (most recent call last):
  File "/home/airflow/.local/lib/python3.7/site-packages/airflow/operators/python.py", line 175, in execute
    return_value = self.execute_callable()
  File "/home/airflow/.local/lib/python3.7/site-packages/airflow/operators/python.py", line 192, in execute_callable
    return self.python_callable(*self.op_args, **self.op_kwargs)
  File "/opt/airflow/dags/test.py", line 61, in load_csv_from_bucket
    blob.download_to_filename("/tmp/" + filename)
  File "/home/airflow/.local/lib/python3.7/site-packages/google/cloud/storage/blob.py", line 1270, in download_to_filename
    retry=retry,
  File "/home/airflow/.local/lib/python3.7/site-packages/google/cloud/storage/client.py", line 1096, in download_blob_to_file
    retry=retry,
  File "/home/airflow/.local/lib/python3.7/site-packages/google/cloud/storage/blob.py", line 984, in _do_download
    response = download.consume(transport, timeout=timeout)
  File "/home/airflow/.local/lib/python3.7/site-packages/google/resumable_media/requests/download.py", line 238, in consume
    retriable_request, self._get_status_code, self._retry_strategy
  File "/home/airflow/.local/lib/python3.7/site-packages/google/resumable_media/requests/_request_helpers.py", line 148, in wait_and_retry
    response = func()
  File "/home/airflow/.local/lib/python3.7/site-packages/google/resumable_media/requests/download.py", line 233, in retriable_request
    self._write_to_stream(result)
  File "/home/airflow/.local/lib/python3.7/site-packages/google/resumable_media/requests/download.py", line 141, in _write_to_stream
    raise common.DataCorruption(response, msg)
google.resumable_media.common.DataCorruption: Checksum mismatch while downloading:

  https://storage.googleapis.com/download/storage/v1/b/test-chr-ml/o/primary%2Fdata.csv%2Fcensus_income_learn.csv?generation=1679778413585655&alt=media

The X-Goog-Hash header indicated an MD5 checksum of:

  iH9NxBCpm8MyvduwpBlbiA==

but the actual MD5 checksum of the downloaded contents was:

  FH1ilt/aFjUQstIj8duYmw==

[2023-03-29T14:44:29.736+0000] {taskinstance.py:1326} INFO - Marking task as FAILED. dag_id=my_dag, task_id=extract_and_load, execution_date=20230329T142000, start_date=20230329T142646, end_date=20230329T144429
[2023-03-29T14:44:32.933+0000] {standard_task_runner.py:105} ERROR - Failed to execute job 402 for task extract_and_load (Checksum mismatch while downloading:

  https://storage.googleapis.com/download/storage/v1/b/test-chr-ml/o/primary%2Fdata.csv%2Fcensus_income_learn.csv?generation=1679778413585655&alt=media

The X-Goog-Hash header indicated an MD5 checksum of:

  iH9NxBCpm8MyvduwpBlbiA==

but the actual MD5 checksum of the downloaded contents was:

  FH1ilt/aFjUQstIj8duYmw==
; 2582)
[2023-03-29T14:44:35.790+0000] {local_task_job.py:212} INFO - Task exited with return code 1
[2023-03-29T14:44:39.075+0000] {taskinstance.py:2585} INFO - 0 downstream tasks scheduled from follow-on schedule check
